<robot name="maggie">
    <!-- MATERIALS -->

    <material name="blue">
        <color rgba="0 0 .8 1" />
    </material>

    <material name="black">
        <color rgba="0 0 0 1" />
    </material>

    <material name="white">
        <color rgba="1 1 1 1" />
    </material>

    <!-- BODY -->

    <link name="base_link">
        <visual>
            <geometry>
                <cylinder length="0.5" radius="0.2" />
            </geometry>

            <material name="white" />
        </visual>

        <collision>
            <geometry>
                <cylinder length="0.5" radius="0.2" />
            </geometry>
        </collision>

        <inertial>
            <mass value="20" />
            <inertia ixx="1.0" ixy="0.0" ixz="0.0" iyy="1.0" iyz="0.0" izz="1.0" />
        </inertial>
    </link>

    <link name="upper_base_link">
        <visual>
            <geometry>
                <cylinder length="0.5" radius="0.2" />
            </geometry>

            <material name="blue" />
        </visual>

        <collision>
            <geometry>
                <cylinder length="0.5" radius="0.2" />
            </geometry>
        </collision>
        
        <inertial>
            <mass value="20" />
            <inertia ixx="1.0" ixy="0.0" ixz="0.0" iyy="1.0" iyz="0.0" izz="1.0" />
        </inertial>
    </link>

    <joint name="base_to_upper_base_joint" type="fixed">
        <parent link="base_link" />
        <child link="upper_base_link" />

        <origin xyz="0 0 0.5" />
    </joint>

    <!-- HEAD -->

    <link name="link_virtual" />

    <joint name="base_to_pan_head_joint" type="revolute">
        <parent link="upper_base_link" />
        <child link="link_virtual" />

        <origin xyz="0 0 0.45" />
        <axis xyz="0 0 1" />
        <limit effort="1000.0" lower="-1.57075" upper="1.57075" velocity="0.5" />
    </joint>

    <link name="head_link">
        <visual>
            <geometry>
                <sphere radius="0.2" />
            </geometry>

            <material name="white" />
        </visual>

        <collision>
            <geometry>
                <sphere radius="0.2" />
            </geometry>
        </collision>
        
        <inertial>
            <mass value="5" />
            <inertia ixx="1.0" ixy="0.0" ixz="0.0" iyy="1.0" iyz="0.0" izz="1.0" />
        </inertial>
    </link>

    <joint name="base_to_tilt_head_joint" type="revolute">
        <parent link="link_virtual" />
        <child link="head_link" />

        <origin xyz="0 0 0" />
        <axis xyz="1 0 0" />
        <limit effort="1000.0" lower="-0.26" upper="0.26" velocity="0.5" />
    </joint>

    <!-- MOUTH -->

    <link name="mouth_link">
        <visual>
            <geometry>
                <box size="0.1 0.02 0.02" />
            </geometry>

            <material name="black" />
        </visual>

        <collision>
            <geometry>
                <box size="0.1 0.02 0.02" />
            </geometry>
        </collision>
        
        <inertial>
            <mass value="0.02" />
            <inertia ixx="1.0" ixy="0.0" ixz="0.0" iyy="1.0" iyz="0.0" izz="1.0" />
        </inertial>
    </link>

    <joint name="head_to_mouth_joint" type="fixed">
        <parent link="head_link" />
        <child link="mouth_link" />

        <origin xyz="0 0.17 -0.1" />
    </joint>

    <!-- EYES -->

    <link name="left_eye_link">
        <visual>
            <geometry>
                <sphere radius="0.05" />
            </geometry>

            <material name="black" />
        </visual>

        <collision>
            <geometry>
                <sphere radius="0.05" />
            </geometry>
        </collision>
        
        <inertial>
            <mass value="0.01" />
            <inertia ixx="1.0" ixy="0.0" ixz="0.0" iyy="1.0" iyz="0.0" izz="1.0" />
        </inertial>
    </link>

    <joint name="head_to_left_eye_joint" type="fixed">
        <parent link="head_link" />
        <child link="left_eye_link" />

        <origin xyz="-0.06 0.16 0.05" />
    </joint>

    <link name="right_eye_link">
        <visual>
            <geometry>
                <sphere radius="0.05" />
            </geometry>

            <material name="black" />
        </visual>

        <collision>
            <geometry>
                <sphere radius="0.05" />
            </geometry>
        </collision>
        
        <inertial>
            <mass value="0.01" />
            <inertia ixx="1.0" ixy="0.0" ixz="0.0" iyy="1.0" iyz="0.0" izz="1.0" />
        </inertial>
    </link>

    <joint name="head_to_right_eye_joint" type="fixed">
        <parent link="head_link" />
        <child link="right_eye_link" />

        <origin xyz="0.06 0.16 0.05" />
    </joint>

    <!-- ARMS -->

    <link name="left_arm_link">
        <visual>
            <origin xyz="0 0 -0.2" rpy="0 1.57075 0" />

            <geometry>
                <box size="0.4 0.2 0.1" />
            </geometry>

            <material name="white" />
        </visual>

        <collision>
            <origin xyz="0 0 -0.2" rpy="0 1.57075 0" />

            <geometry>
                <box size="0.4 0.2 0.1" />
            </geometry>
        </collision>
        
        <inertial>
            <mass value="1" />
            <inertia ixx="1.0" ixy="0.0" ixz="0.0" iyy="1.0" iyz="0.0" izz="1.0" />
        </inertial>
    </link>

    <joint name="base_to_left_arm_joint" type="revolute">
        <parent link="upper_base_link" />
        <child link="left_arm_link" />

        <origin xyz="-0.25 0 0.25" />
        <axis xyz="1 0 0" />
        <limit effort="1000.0" lower="-1.05" upper="2.69" velocity="0.5" />
    </joint>

    <link name="right_arm_link">
        <visual>
            <origin xyz="0 0 -0.2" rpy="0 1.57075 0" />

            <geometry>
                <box size="0.4 0.2 0.1" />
            </geometry>

            <material name="white" />
        </visual>

        <collision>
            <origin xyz="0 0 -0.2" rpy="0 1.57075 0" />

            <geometry>
                <box size="0.4 0.2 0.1" />
            </geometry>
        </collision>
        
        <inertial>
            <mass value="1" />
            <inertia ixx="1.0" ixy="0.0" ixz="0.0" iyy="1.0" iyz="0.0" izz="1.0" />
        </inertial>
    </link>

    <joint name="base_to_right_arm_joint" type="revolute">
        <parent link="upper_base_link" />
        <child link="right_arm_link" />

        <origin xyz="0.25 0 0.25" />
        <axis xyz="1 0 0" />
        <limit effort="1000.0" lower="-1.05" upper="2.69" velocity="0.5" />
    </joint>

    <!-- SCREEN -->

    <link name="screen_link">
        <visual>
            <geometry>
                <box size="0.2 0.02 0.25" />
            </geometry>

            <material name="black" />
        </visual>

        <collision>
            <geometry>
                <box size="0.2 0.02 0.25" />
            </geometry>
        </collision>
        
        <inertial>
            <mass value="2" />
            <inertia ixx="1.0" ixy="0.0" ixz="0.0" iyy="1.0" iyz="0.0" izz="1.0" />
        </inertial>
    </link>

    <joint name="base_to_screen_joint" type="fixed">
        <parent link="upper_base_link" />
        <child link="screen_link" />

        <origin xyz="0 0.19 0" />
    </joint>

    <!-- WHEELS -->

    <link name="left_wheel_link">
        <visual>
            <origin xyz="0 0 0" rpy="0 0 1.57075" />

            <geometry>
                <mesh filename="package://maggie_description/meshes/base/wheel.dae" />
            </geometry>
        </visual>

        <collision>
            <origin xyz="0 0 0" rpy="0 0 1.57075" />

            <geometry>
                <mesh filename="package://maggie_description/meshes/base/wheel.dae" />
            </geometry>
        </collision>
        
        <inertial>
            <mass value="1" />
            <inertia ixx="1.0" ixy="0.0" ixz="0.0" iyy="1.0" iyz="0.0" izz="1.0" />
        </inertial>
    </link>

    <joint name="base_to_left_wheel_joint" type="continuous">
        <parent link="base_link" />
        <child link="left_wheel_link" />

        <origin xyz="0.1 0 -0.2" rpy="0 0 0" />
        <axis xyz="1 0 0" rpy="0 0 0" />
    </joint>

    <link name="right_wheel_link">
        <visual>
            <origin xyz="0 0 0" rpy="0 0 1.57075" />

            <geometry>
                <mesh filename="package://maggie_description/meshes/base/wheel.dae" />
            </geometry>
        </visual>

        <collision>
            <origin xyz="0 0 0" rpy="0 0 1.57075" />

            <geometry>
                <mesh filename="package://maggie_description/meshes/base/wheel.dae" />
            </geometry>
        </collision>
        
        <inertial>
            <mass value="1" />
            <inertia ixx="1.0" ixy="0.0" ixz="0.0" iyy="1.0" iyz="0.0" izz="1.0" />
        </inertial>
    </link>

    <joint name="base_to_right_wheel_joint" type="continuous">
        <parent link="base_link" />
        <child link="right_wheel_link" />

        <origin xyz="-0.1 0 -0.2" rpy="0 0 0" />
        <axis xyz="1 0 0" rpy="0 0 0" />
    </joint>

    <!-- SENSORS -->

    <link name="kinect_link">
        <visual>
            <origin xyz="0 0 0" rpy="0 0 1.57075" />

            <geometry>
                <mesh filename="package://maggie_description/meshes/kinect/kinect.dae" scale="0.001 0.001 0.001" />
            </geometry>
        </visual>

        <collision>
            <origin xyz="0 0 0" rpy="0 0 1.57075" />

            <geometry>
                <mesh filename="package://maggie_description/meshes/kinect/kinect.dae" scale="0.001 0.001 0.001" />
            </geometry>
        </collision>
        
        <inertial>
            <mass value="2" />
            <inertia ixx="1.0" ixy="0.0" ixz="0.0" iyy="1.0" iyz="0.0" izz="1.0" />
        </inertial>
    </link>

    <joint name="base_to_kinect_joint" type="fixed">
        <parent link="base_link" />
        <child link="kinect_link" />

        <origin xyz="0 0.25 0.25" rpy="0 0 0" />
    </joint>
</robot>
