<?xml version="1.0" ?>
<!-- =================================================================================== -->
<!-- |    This document was autogenerated by xacro from robots/maggie.urdf.xacro       | -->
<!-- |    EDITING THIS FILE BY HAND IS NOT RECOMMENDED                                 | -->
<!-- =================================================================================== -->
<robot name="maggie" xmlns:xacro="http://www.ros.org/wiki/xacro">
  <!-- MATERIALS -->
  <material name="blue">
    <color rgba="0 0 .8 1"/>
  </material>
  <material name="black">
    <color rgba="0 0 0 1"/>
  </material>
  <material name="white">
    <color rgba="1 1 1 1"/>
  </material>
  <!-- CONSTANTS & COMMON MACROS -->
  <!-- CONSTANTS -->
  <!-- MACROS -->
  <!-- BODY -->
  <link name="base_link">
    <visual>
      <origin xyz="0 0 0.26"/>
      <geometry>
        <cylinder length="0.42" radius="0.2"/>
      </geometry>
      <material name="white"/>
    </visual>
    <collision>
      <geometry>
        <cylinder length="0.42" radius="0.2"/>
      </geometry>
    </collision>
    <inertial>
      <mass value="20"/>
      <inertia ixx="1.0" ixy="0.0" ixz="0.0" iyy="1.0" iyz="0.0" izz="1.0"/>
    </inertial>
  </link>
  <link name="upper_base_link">
    <visual>
      <geometry>
        <cylinder length="0.56" radius="0.2"/>
      </geometry>
      <material name="blue"/>
    </visual>
    <collision>
      <geometry>
        <cylinder length="0.56" radius="0.2"/>
      </geometry>
    </collision>
    <inertial>
      <mass value="20"/>
      <inertia ixx="1.0" ixy="0.0" ixz="0.0" iyy="1.0" iyz="0.0" izz="1.0"/>
    </inertial>
  </link>
  <joint name="base_to_upper_base_joint" type="fixed">
    <parent link="base_link"/>
    <child link="upper_base_link"/>
    <origin xyz="0 0 0.75"/>
  </joint>
  <!-- NECK -->
  <link name="neck_link">
    <visual>
      <geometry>
        <cylinder length="0.05" radius="0.04"/>
      </geometry>
      <material name="black"/>
    </visual>
    <collision>
      <geometry>
        <cylinder length="0.05" radius="0.02"/>
      </geometry>
    </collision>
    <inertial>
      <mass value="0.2"/>
      <inertia ixx="1.0" ixy="0.0" ixz="0.0" iyy="1.0" iyz="0.0" izz="1.0"/>
    </inertial>
  </link>
  <joint name="base_to_neck_joint" type="fixed">
    <parent link="upper_base_link"/>
    <child link="neck_link"/>
    <origin xyz="0 0 0.305"/>
  </joint>
  <!-- HEAD -->
  <link name="virtual_link"/>
  <joint name="neck_to_pan_head_joint" type="revolute">
    <parent link="neck_link"/>
    <child link="virtual_link"/>
    <origin xyz="0 0 0.2"/>
    <axis xyz="0 0 1"/>
    <limit effort="1000.0" lower="-1.57075" upper="1.57075" velocity="0.5"/>
  </joint>
  <link name="head_link">
    <visual>
      <geometry>
        <sphere radius="0.2"/>
      </geometry>
      <material name="white"/>
    </visual>
    <collision>
      <geometry>
        <sphere radius="0.2"/>
      </geometry>
    </collision>
    <inertial>
      <mass value="5"/>
      <inertia ixx="1.0" ixy="0.0" ixz="0.0" iyy="1.0" iyz="0.0" izz="1.0"/>
    </inertial>
  </link>
  <joint name="base_to_tilt_head_joint" type="revolute">
    <parent link="virtual_link"/>
    <child link="head_link"/>
    <origin xyz="0 0 0"/>
    <axis xyz="1 0 0"/>
    <limit effort="1000.0" lower="-0.26" upper="0.26" velocity="0.5"/>
  </joint>
  <!-- MOUTH -->
  <link name="mouth_link">
    <visual>
      <geometry>
        <box size="0.1 0.02 0.02"/>
      </geometry>
      <material name="black"/>
    </visual>
    <collision>
      <geometry>
        <box size="0.1 0.02 0.02"/>
      </geometry>
    </collision>
    <inertial>
      <mass value="0.02"/>
      <inertia ixx="1.0" ixy="0.0" ixz="0.0" iyy="1.0" iyz="0.0" izz="1.0"/>
    </inertial>
  </link>
  <joint name="head_to_mouth_joint" type="fixed">
    <parent link="head_link"/>
    <child link="mouth_link"/>
    <origin xyz="0 0.17 -0.1"/>
  </joint>
  <!-- EYES -->
  <link name="left_eye_link">
    <visual>
      <geometry>
        <sphere radius="0.05"/>
      </geometry>
      <material name="black"/>
    </visual>
    <collision>
      <geometry>
        <sphere radius="0.05"/>
      </geometry>
    </collision>
    <inertial>
      <mass value="0.01"/>
      <inertia ixx="1.0" ixy="0.0" ixz="0.0" iyy="1.0" iyz="0.0" izz="1.0"/>
    </inertial>
  </link>
  <joint name="head_to_left_eye_joint" type="fixed">
    <parent link="head_link"/>
    <child link="left_eye_link"/>
    <origin xyz="0.16 -0.06 0.05"/>
  </joint>
  <link name="right_eye_link">
    <visual>
      <geometry>
        <sphere radius="0.05"/>
      </geometry>
      <material name="black"/>
    </visual>
    <collision>
      <geometry>
        <sphere radius="0.05"/>
      </geometry>
    </collision>
    <inertial>
      <mass value="0.01"/>
      <inertia ixx="1.0" ixy="0.0" ixz="0.0" iyy="1.0" iyz="0.0" izz="1.0"/>
    </inertial>
  </link>
  <joint name="head_to_right_eye_joint" type="fixed">
    <parent link="head_link"/>
    <child link="right_eye_link"/>
    <origin xyz="0.16 0.06 0.05"/>
  </joint>
  <!-- ARMS -->
  <link name="left_arm_link">
    <visual>
      <origin rpy="0 1.57075 1.57075" xyz="0 0 -0.19"/>
      <geometry>
        <box size="0.38 0.15 0.1"/>
      </geometry>
      <material name="white"/>
    </visual>
    <collision>
      <origin rpy="0 1.57075 0" xyz="0 0 -0.2"/>
      <geometry>
        <box size="0.38 0.15 0.1"/>
      </geometry>
    </collision>
    <inertial>
      <mass value="1"/>
      <inertia ixx="1.0" ixy="0.0" ixz="0.0" iyy="1.0" iyz="0.0" izz="1.0"/>
    </inertial>
  </link>
  <joint name="base_to_left_arm_joint" type="revolute">
    <parent link="upper_base_link"/>
    <child link="left_arm_link"/>
    <origin xyz="0 -0.25 0.28"/>
    <axis xyz="1 0 0"/>
    <limit effort="1000.0" lower="-1.04716666667" upper="2.356125" velocity="0.5"/>
  </joint>
  <link name="right_arm_link">
    <visual>
      <origin rpy="0 1.57075 1.57075" xyz="0 0 -0.19"/>
      <geometry>
        <box size="0.38 0.15 0.1"/>
      </geometry>
      <material name="white"/>
    </visual>
    <collision>
      <origin rpy="0 1.57075 0" xyz="0 0 -0.2"/>
      <geometry>
        <box size="0.38 0.15 0.1"/>
      </geometry>
    </collision>
    <inertial>
      <mass value="1"/>
      <inertia ixx="1.0" ixy="0.0" ixz="0.0" iyy="1.0" iyz="0.0" izz="1.0"/>
    </inertial>
  </link>
  <joint name="base_to_right_arm_joint" type="revolute">
    <parent link="upper_base_link"/>
    <child link="right_arm_link"/>
    <origin xyz="0 0.25 0.28"/>
    <axis xyz="1 0 0"/>
    <limit effort="1000.0" lower="-1.04716666667" upper="2.356125" velocity="0.5"/>
  </joint>
  <!-- SCREEN -->
  <link name="screen_link">
    <visual>
      <geometry>
        <box size="0.16 0.02 0.21"/>
      </geometry>
      <material name="black"/>
    </visual>
    <collision>
      <geometry>
        <box size="0.16 0.02 0.21"/>
      </geometry>
    </collision>
    <inertial>
      <mass value="2"/>
      <inertia ixx="1.0" ixy="0.0" ixz="0.0" iyy="1.0" iyz="0.0" izz="1.0"/>
    </inertial>
  </link>
  <joint name="base_to_screen_joint" type="fixed">
    <parent link="upper_base_link"/>
    <child link="screen_link"/>
    <origin xyz="0 0.19 0.105"/>
  </joint>
  <!-- WHEELS -->
  <link name="left_wheel_link">
    <visual>
      <origin rpy="0 0 0" xyz="0 0 0"/>
      <geometry>
        <mesh filename="package://maggie_description/meshes/base/wheel.dae"/>
      </geometry>
    </visual>
    <collision>
      <origin rpy="0 0 0" xyz="0 0 0"/>
      <geometry>
        <mesh filename="package://maggie_description/meshes/base/wheel.dae"/>
      </geometry>
    </collision>
    <inertial>
      <mass value="1"/>
      <inertia ixx="1.0" ixy="0.0" ixz="0.0" iyy="1.0" iyz="0.0" izz="1.0"/>
    </inertial>
  </link>
  <joint name="base_to_left_wheel_joint" type="continuous">
    <parent link="base_link"/>
    <child link="left_wheel_link"/>
    <origin rpy="0 0 0" xyz="0 -0.1 0.08"/>
    <axis rpy="0 0 0" xyz="1 0 0"/>
  </joint>
  <link name="right_wheel_link">
    <visual>
      <origin rpy="0 0 0" xyz="0 0 0"/>
      <geometry>
        <mesh filename="package://maggie_description/meshes/base/wheel.dae"/>
      </geometry>
    </visual>
    <collision>
      <origin rpy="0 0 0" xyz="0 0 0"/>
      <geometry>
        <mesh filename="package://maggie_description/meshes/base/wheel.dae"/>
      </geometry>
    </collision>
    <inertial>
      <mass value="1"/>
      <inertia ixx="1.0" ixy="0.0" ixz="0.0" iyy="1.0" iyz="0.0" izz="1.0"/>
    </inertial>
  </link>
  <joint name="base_to_right_wheel_joint" type="continuous">
    <parent link="base_link"/>
    <child link="right_wheel_link"/>
    <origin rpy="0 0 0" xyz="0 0.1 0.08"/>
    <axis rpy="0 0 0" xyz="1 0 0"/>
  </joint>
  <!-- RFID -->
  <link name="rfid_link">
    <inertial>
      <mass value="0.02"/>
      <inertia ixx="1.0" ixy="0.0" ixz="0.0" iyy="1.0" iyz="0.0" izz="1.0"/>
    </inertial>
  </link>
  <joint name="head_to_rfid_joint" type="fixed">
    <parent link="head_link"/>
    <child link="rfid_link"/>
    <origin rpy="0 0 0" xyz="0 0.2 0"/>
  </joint>
  <!-- IR CONTROLLER -->
  <link name="ir_link">
    <inertial>
      <mass value="0.02"/>
      <inertia ixx="1.0" ixy="0.0" ixz="0.0" iyy="1.0" iyz="0.0" izz="1.0"/>
    </inertial>
  </link>
  <joint name="base_to_ir_joint" type="fixed">
    <parent link="base_link"/>
    <child link="ir_link"/>
    <origin rpy="0 0 0" xyz="0 0.2 0.56"/>
  </joint>
  <!-- LASERS -->
  <link name="sick_link">
    <inertial>
      <mass value="5"/>
      <inertia ixx="1.0" ixy="0.0" ixz="0.0" iyy="1.0" iyz="0.0" izz="1.0"/>
    </inertial>
  </link>
  <joint name="base_to_sick_joint" type="fixed">
    <parent link="base_link"/>
    <child link="sick_link"/>
    <origin rpy="0 0 0" xyz="0 0.2 0.26"/>
  </joint>
  <link name="hokuyo_link">
    <inertial>
      <mass value="1"/>
      <inertia ixx="1.0" ixy="0.0" ixz="0.0" iyy="1.0" iyz="0.0" izz="1.0"/>
    </inertial>
  </link>
  <joint name="base_to_hokuyo_joint" type="fixed">
    <parent link="base_link"/>
    <child link="hokuyo_link"/>
    <origin rpy="0 0 -3.1415" xyz="0 -0.2 0.46"/>
  </joint>
  <!-- TOUCH SENSORS -->
  <link name="touch_head_link">
    <inertial>
      <mass value="0.01"/>
      <inertia ixx="1.0" ixy="0.0" ixz="0.0" iyy="1.0" iyz="0.0" izz="1.0"/>
    </inertial>
  </link>
  <joint name="head_to_touch_head_joint" type="fixed">
    <parent link="head_link"/>
    <child link="touch_head_link"/>
    <origin rpy="0 0 0" xyz="0 0 0.2"/>
  </joint>
  <link name="touch_left_back_link">
    <inertial>
      <mass value="0.01"/>
      <inertia ixx="1.0" ixy="0.0" ixz="0.0" iyy="1.0" iyz="0.0" izz="1.0"/>
    </inertial>
  </link>
  <joint name="arm_to_touch_left_back_joint" type="fixed">
    <parent link="upper_base_link"/>
    <child link="touch_left_back_link"/>
    <origin rpy="0 0 0" xyz="-0.1 -0.18 0.18"/>
  </joint>
  <link name="touch_right_back_link">
    <inertial>
      <mass value="0.01"/>
      <inertia ixx="1.0" ixy="0.0" ixz="0.0" iyy="1.0" iyz="0.0" izz="1.0"/>
    </inertial>
  </link>
  <joint name="arm_to_touch_right_back_joint" type="fixed">
    <parent link="upper_base_link"/>
    <child link="touch_right_back_link"/>
    <origin rpy="0 0 0" xyz="0.1 -0.18 0.18"/>
  </joint>
  <link name="touch_left_shoulder_link">
    <inertial>
      <mass value="0.01"/>
      <inertia ixx="1.0" ixy="0.0" ixz="0.0" iyy="1.0" iyz="0.0" izz="1.0"/>
    </inertial>
  </link>
  <joint name="arm_to_touch_left_shoulder_joint" type="fixed">
    <parent link="upper_base_link"/>
    <child link="touch_left_shoulder_link"/>
    <origin rpy="0 0 0" xyz="-0.1 0 0.28"/>
  </joint>
  <link name="touch_right_shoulder_link">
    <inertial>
      <mass value="0.01"/>
      <inertia ixx="1.0" ixy="0.0" ixz="0.0" iyy="1.0" iyz="0.0" izz="1.0"/>
    </inertial>
  </link>
  <joint name="arm_to_touch_right_shoulder_joint" type="fixed">
    <parent link="upper_base_link"/>
    <child link="touch_right_shoulder_link"/>
    <origin rpy="0 0 0" xyz="0.1 0 0.28"/>
  </joint>
  <link name="touch_left_hand_link">
    <inertial>
      <mass value="0.01"/>
      <inertia ixx="1.0" ixy="0.0" ixz="0.0" iyy="1.0" iyz="0.0" izz="1.0"/>
    </inertial>
  </link>
  <joint name="arm_to_touch_left_hand_joint" type="fixed">
    <parent link="left_arm_link"/>
    <child link="touch_left_hand_link"/>
    <origin rpy="0 0 0" xyz="0.05 0 -0.36"/>
  </joint>
  <link name="touch_right_hand_link">
    <inertial>
      <mass value="0.01"/>
      <inertia ixx="1.0" ixy="0.0" ixz="0.0" iyy="1.0" iyz="0.0" izz="1.0"/>
    </inertial>
  </link>
  <joint name="arm_to_touch_right_hand_joint" type="fixed">
    <parent link="right_arm_link"/>
    <child link="touch_right_hand_link"/>
    <origin rpy="0 0 0" xyz="-0.05 0 -0.36"/>
  </joint>
  <!-- CAMERAS -->
  <link name="kinect_link">
    <visual>
      <origin rpy="0 0 1.57075" xyz="0 0 0"/>
      <geometry>
        <mesh filename="package://maggie_description/meshes/kinect/kinect.dae" scale="0.001 0.001 0.001"/>
      </geometry>
    </visual>
    <collision>
      <origin rpy="0 0 1.57075" xyz="0 0 0"/>
      <geometry>
        <mesh filename="package://maggie_description/meshes/kinect/kinect.dae" scale="0.001 0.001 0.001"/>
      </geometry>
    </collision>
    <inertial>
      <mass value="2"/>
      <inertia ixx="1.0" ixy="0.0" ixz="0.0" iyy="1.0" iyz="0.0" izz="1.0"/>
    </inertial>
  </link>
  <joint name="base_to_kinect_joint" type="fixed">
    <parent link="base_link"/>
    <child link="kinect_link"/>
    <origin rpy="0 0 0" xyz="0 0.26 0.49"/>
  </joint>
  <link name="webcam_link">
    <inertial>
      <mass value="0.03"/>
      <inertia ixx="1.0" ixy="0.0" ixz="0.0" iyy="1.0" iyz="0.0" izz="1.0"/>
    </inertial>
  </link>
  <joint name="mouth_to_webcam_joint" type="fixed">
    <parent link="mouth_link"/>
    <child link="webcam_link"/>
    <origin rpy="0 0 0" xyz="0 0 0"/>
  </joint>
</robot>

